Workbook
Name Slicer_Gender: #N/A
Name Slicer_Gibson__Hobbs_and_Weaver: #N/A
Name Slicer_STORE0: #N/A
Name Slicer_Years__Order_Date: #N/A

Sheet Customer_Dim
A1: Customer_ID | B1: Age | C1: Gender | D1: State | E1: Country | F1: Loyalty_Level
A2: CUST1000 | B2: 55 | C2: Male | D2: North Carolina | E2: USA | F2: =IF(ISBLANK(F20),"UNKNOWN",F20) -> UNKNOWN
A3: CUST1001 | B3: 26 | C3: Female | D3: North Dakota | E3: USA | F3: Platinum
A4: CUST1002 | B4: 29 | C4: Female | D4: Alabama | E4: USA | F4: Platinum | H4: WHAT IS THE AVERAGE AGE OF ACUSTOMER | K4: CUSTOMER? | L4: ?
A5: CUST1003 | B5: 59 | C5: Female | D5: Ohio | E5: USA | F5: Bronze
A6: CUST1004 | B6: 64 | C6: Female | D6: California | E6: USA | F6: Silver | H6: =AVERAGE(B:B) -> 41.562 | J6: Average b:b
A7: CUST1005 | B7: 24 | C7: Male | D7: Oregon | E7: USA | F7: Bronze
A8: CUST1006 | B8: 29 | C8: Female | D8: South Dakota | E8: USA | F8: Platinum | H8: IN LOYALTY HOW MANY PLATINUM ARE THERE IN LOYALTY?
A9: CUST1007 | B9: 29 | C9: Female | D9: West Virginia | E9: USA | F9: Bronze
A10: CUST1008 | B10: 53 | C10: Female | D10: New Hampshire | E10: USA | F10: Gold | H10: =COUNTIF(F:F,"Platinum") -> 145 | J10: countif(f:f "platinum)
A11: CUST1009 | B11: 64 | C11: Male | D11: Pennsylvania | E11: USA | F11: Platinum
A12: CUST1010 | B12: 53 | C12: Male | D12: Pennsylvania | E12: USA | F12: Bronze
A13: CUST1011 | B13: 28 | C13: Female | D13: New York | E13: USA | F13: Gold
A14: CUST1012 | B14: 55 | C14: Female | D14: Kansas | E14: USA | F14: Platinum
A15: CUST1013 | B15: 32 | C15: Female | D15: Montana | E15: USA | F15: Silver
A16: CUST1014 | B16: 53 | C16: Female | D16: Nebraska | E16: USA | F16: Silver
A17: CUST1015 | B17: 49 | C17: Female | D17: Washington | E17: USA | F17: Platinum
A18: CUST1016 | B18: 24 | C18: Female | D18: Pennsylvania | E18: USA | F18: Bronze
A19: CUST1017 | B19: 60 | C19: Female | D19: Georgia | E19: USA | F19: Platinum
A20: CUST1018 | B20: 43 | C20: Male | D20: Kansas | E20: USA | F20: UNKNOWN
A21: CUST1019 | B21: 46 | C21: Female | D21: New Jersey | E21: USA | F21: Platinum
A22: CUST1020 | B22: 59 | C22: Male | D22: Delaware | E22: USA | F22: Silver
... A501: CUST1499 | B501: 27 | C501: Female | D501: Oregon | E501: USA | F501: Platinum

Sheet Product_Dim
A1: Product_ID | B1: Category | C1: Brand | D1: Stock
A2: PROD0 | B2: Electronics | C2: Hunt Inc | D2: 416
A3: PROD1 | B3: Clothing | C3: Terry-Moore | D3: 181
A4: PROD2 | B4: Clothing | C4: Sims Inc | D4: 352
A5: PROD3 | B5: Clothing | C5: Pineda Ltd | D5: 452
A6: PROD4 | B6: Clothing | C6: Gonzales-Davis | D6: 487 | F6: HIGLIGHT HOME USING CONDITIONAL FORMATING
A7: PROD5 | B7: Clothing | C7: Baldwin, Garza and Gonzalez | D7: 59
A8: PROD6 | B8: Beauty | C8: Davidson PLC | D8: 350
A9: PROD7 | B9: Home | C9: Harrell LLC | D9: 170
A10: PROD8 | B10: Electronics | C10: Perez-Johnston | D10: 142
A11: PROD9 | B11: Sports | C11: Hill PLC | D11: 323
A12: PROD10 | B12: Home | C12: Hamilton Group | D12: 308
A13: PROD11 | B13: Electronics | C13: Gibson, Hobbs and Weaver | D13: =COUNTBLANK(D:D) -> 0
A14: PROD12 | B14: Beauty | C14: Rice LLC | D14: 460
A15: PROD13 | B15: Electronics | C15: Dawson-Perkins | D15: 453
A16: PROD14 | B16: Home | C16: Luna, Anderson and Bowman | D16: 439
A17: PROD15 | B17: Electronics | C17: Thomas LLC | D17: 301
A18: PROD16 | B18: Beauty | C18: Erickson-Green | D18: 256
A19: PROD17 | B19: Sports | C19: Ford, Murphy and Wilson | D19: 367
A20: PROD18 | B20: Clothing | C20: Guerra-Hendrix | D20: 343
A21: PROD19 | B21: Sports | C21: May-Reese | D21: 65
A22: PROD20 | B22: Sports | C22: Soto-Ellis | D22: =COUNTBLANK(D:D) -> 0
A23: PROD21 | B23: Home | C23: Gardner-Montes | D23: 76
A24: PROD22 | B24: Sports | C24: Flores, Pineda and Rodriguez | D24: 432
A25: PROD23 | B25: Clothing | C25: Moon, Mora and Santos | D25: 360
A26: PROD24 | B26: Sports | C26: Cook Ltd | D26: 340
A27: PROD25 | B27: Clothing | C27: Brown and Sons | D27: 268
A28: PROD26 | B28: Electronics | C28: Reed-Schmidt | D28: 213
A29: PROD27 | B29: Home | C29: Khan, Jones and Paul | D29: 378
A30: PROD28 | B30: Sports | C30: Burns-Hansen | D30: 137
A31: PROD29 | B31: Home | C31: Hoffman Group | D31: 276
A32: PROD30 | B32: Home | C32: Stevens, Fernandez and Martin | D32: 57
A33: PROD31 | B33: Sports | C33: Nolan-Snow | D33: 281
A34: PROD32 | B34: Beauty | C34: Griffin Ltd | D34: 244
... A56: PROD54 | B56: Sports | C56: Thompson-French | D56: 185
A57: PROD55 | B57: Home | C57: Hatfield, Baird and Torres | D57: =COUNTBLANK(D:D) -> 0
A58: PROD56 | B58: Home | C58: Hernandez, Kennedy and Porter | D58: 190
A59: PROD57 | B59: Sports | C59: Atkinson, Camacho and Oliver | D59: 138
A60: PROD58 | B60: Clothing | C60: Shepherd-Gould | D60: 485
A61: PROD59 | B61: Beauty | C61: Cline-Mccarthy | D61: 399
...

Sheet Store_Dim
A1: Store_ID | B1: Store_Name | C1: REGION CITY | D1: Region | E1: City | F1: Store_Type
A2: STORE0 | B2: Rivera-Warner | C2: =_xlfn.CONCAT(D2:E2) -> EastWashingtonfurt | D2: East | E2: Washingtonfurt | F2: Flagship
A3: STORE1 | B3: Martinez, Adkins and Johnson | C3: =_xlfn.CONCAT(D3:E3) -> NorthDanielmouth | D3: North | E3: Danielmouth | F3: Flagship
A4: STORE2 | B4: Black-Horn | C4: =_xlfn.CONCAT(D4:E4) -> SouthNorth Nancyview | D4: South | E4: North Nancyview | F4: Outlet
A5: STORE3 | B5: Johnson-Wright | C5: =_xlfn.CONCAT(D5:E5) -> NorthHoodberg | D5: North | E5: Hoodberg | F5: Outlet
A6: STORE4 | B6: Alexander Group | C6: =_xlfn.CONCAT(D6:E6) -> SouthPort Sharon | D6: South | E6: Port Sharon | F6: Online
A7: STORE5 | B7: Gray Ltd | C7: =_xlfn.CONCAT(D7:E7) -> NorthNew Michaelchester | D7: North | E7: New Michaelchester | F7: Outlet
A8: STORE6 | B8: Benson-Elliott | C8: =_xlfn.CONCAT(D8:E8) -> EastPort Josephberg | D8: East | E8: Port Josephberg | F8: Online
A9: STORE7 | B9: Martinez-Mullins | C9: =_xlfn.CONCAT(D9:E9) -> SouthWilliamsfurt | D9: South | E9: Williamsfurt | F9: Online
A10: STORE8 | B10: Bean, Jones and Park | C10: =_xlfn.CONCAT(D10:E10) -> WestThompsonborough | D10: West | E10: Thompsonborough | F10: Online
A11: STORE9 | B11: Moore, Padilla and Butler | C11: =_xlfn.CONCAT(D11:E11) -> SouthEast Johnstad | D11: South | E11: East Johnstad | F11: Flagship
A12: STORE10 | B12: Hill, Wagner and Ballard | C12: =_xlfn.CONCAT(D12:E12) -> EastEast Davidville | D12: East | E12: East Davidville | F12: Online
A13: STORE11 | B13: Aguirre-Keller | C13: =_xlfn.CONCAT(D13:E13) -> SouthLake Michael | D13: South | E13: Lake Michael | F13: Online
... A21: STORE19 | B21: Mann-Austin | C21: =_xlfn.CONCAT(D21:E21) -> EastVasquezborough | D21: East | E21: Vasquezborough | F21: Online

Sheet Sales_Fact
A1: Store_ID | B1: Sales_ID | C1: Product_ID | D1: Order_Date | E1: Customer_ID | F1: Brand | G1: Category | H1: Quantity | I1: Unit_Price | J1: Discount | K1: Total_Amount | L1: Payment_Type | M1: Gender | N1: Country | O1: Loyalty_Level | P1: REGION CITY
A2: STORE0 | B2: SALE638 | C2: PROD11 | D2: 45338 | E2: CUST1390 | F2: =VLOOKUP($C2,Product_Dim!$A$2:$D$101,3,FALSE) -> Gibson, Hobbs and Weaver | G2: =VLOOKUP($C2,Product_Dim!$A$2:$D$101,2,FALSE) -> Electronics | H2: 1 | I2: 362.93 | J2: 0.27 | K2: 264.9389 | L2: Credit Card | M2: =VLOOKUP($E2,Customer_Dim!$A$2:$F$501,3,FALSE) -> Male | N2: =VLOOKUP($E2,Customer_Dim!$A$2:$F$501,5,FALSE) -> USA | O2: =VLOOKUP($E2,Customer_Dim!$A$2:$F$501,6,FALSE) -> Silver | P2: =VLOOKUP($A2,Store_Dim!$A$2:$F$21,3,FALSE) -> EastWashingtonfurt
A3: STORE0 | B3: SALE1727 | C3: PROD12 | D3: 45214 | E3: CUST1023 | F3: =VLOOKUP($C3,Product_Dim!$A$2:$D$101,3,FALSE) -> Rice LLC | G3: =VLOOKUP($C3,Product_Dim!$A$2:$D$101,2,FALSE) -> Beauty | H3: 1 | I3: 145.48 | J3: 0.1 | K3: 130.932 | L3: COD | M3: =VLOOKUP($E3,Customer_Dim!$A$2:$F$501,3,FALSE) -> Female | N3: =VLOOKUP($E3,Customer_Dim!$A$2:$F$501,5,FALSE) -> USA | O3: =VLOOKUP($E3,Customer_Dim!$A$2:$F$501,6,FALSE) -> Silver | P3: =VLOOKUP($A3,Store_Dim!$A$2:$F$21,3,FALSE) -> EastWashingtonfurt
A4: STORE0 | B4: SALE1814 | C4: PROD12 | D4: 45832 | E4: CUST1115 | F4: =VLOOKUP($C4,Product_Dim!$A$2:$D$101,3,FALSE) -> Rice LLC | G4: =VLOOKUP($C4,Product_Dim!$A$2:$D$101,2,FALSE) -> Beauty | H4: 1 | I4: 281.83 | J4: 0.16 | K4: 236.7372 | L4: COD | M4: =VLOOKUP($E4,Customer_Dim!$A$2:$F$501,3,FALSE) -> Female | N4: =VLOOKUP($E4,Customer_Dim!$A$2:$F$501,5,FALSE) -> USA | O4: =VLOOKUP($E4,Customer_Dim!$A$2:$F$501,6,FALSE) -> Platinum | P4: =VLOOKUP($A4,Store_Dim!$A$2:$F$21,3,FALSE) -> EastWashingtonfurt
A5: STORE0 | B5: SALE1917 | C5: PROD12 | D5: 45661 | E5: CUST1466 | F5: =VLOOKUP($C5,Product_Dim!$A$2:$D$101,3,FALSE) -> Rice LLC | G5: =VLOOKUP($C5,Product_Dim!$A$2:$D$101,2,FALSE) -> Beauty | H5: 2 | I5: 687.35 | J5: 0.2 | K5: 1099.76 | L5: COD | M5: =VLOOKUP($E5,Customer_Dim!$A$2:$F$501,3,FALSE) -> Male | N5: =VLOOKUP($E5,Customer_Dim!$A$2:$F$501,5,FALSE) -> USA | O5: =VLOOKUP($E5,Customer_Dim!$A$2:$F$501,6,FALSE) -> Silver | P5: =VLOOKUP($A5,Store_Dim!$A$2:$F$21,3,FALSE) -> EastWashingtonfurt
A6: STORE0 | B6: SALE244 | C6: PROD14 | D6: 45780 | E6: CUST1200 | F6: =VLOOKUP($C6,Product_Dim!$A$2:$D$101,3,FALSE) -> Luna, Anderson and Bowman | G6: =VLOOKUP($C6,Product_Dim!$A$2:$D$101,2,FALSE) -> Home | H6: 4 | I6: 452.67 | J6: 0.28 | K6: 1303.6896 | L6: PayPal | M6: =VLOOKUP($E6,Customer_Dim!$A$2:$F$501,3,FALSE) -> Male | N6: =VLOOKUP($E6,Customer_Dim!$A$2:$F$501,5,FALSE) -> USA | O6: =VLOOKUP($E6,Customer_Dim!$A$2:$F$501,6,FALSE) -> Platinum | P6: =VLOOKUP($A6,Store_Dim!$A$2:$F$21,3,FALSE) -> EastWashingtonfurt
A7: STORE0 | B7: SALE1278 | C7: PROD14 | D7: 45481 | E7: CUST1351 | F7: =VLOOKUP($C7,Product_Dim!$A$2:$D$101,3,FALSE) -> Luna, Anderson and Bowman | G7: =VLOOKUP($C7,Product_Dim!$A$2:$D$101,2,FALSE) -> Home | H7: 2 | I7: 779.29 | J7: 0.12 | K7: 1371.5504 | L7: COD | M7: =VLOOKUP($E7,Customer_Dim!$A$2:$F$501,3,FALSE) -> Female | N7: =VLOOKUP($E7,Customer_Dim!$A$2:$F$501,5,FALSE) -> USA | O7: =VLOOKUP($E7,Customer_Dim!$A$2:$F$501,6,FALSE) -> Bronze | P7: =VLOOKUP($A7,Store_Dim!$A$2:$F$21,3,FALSE) -> EastWashingtonfurt
A8: STORE0 | B8: SALE535 | C8: PROD16 | D8: 45281 | E8: CUST1032 | F8: =VLOOKUP($C8,Product_Dim!$A$2:$D$101,3,FALSE) -> Erickson-Green | G8: =VLOOKUP($C8,Product_Dim!$A$2:$D$101,2,FALSE) -> Beauty | H8: 1 | I8: 791.36 | J8: 0.06 | K8: 743.8784 | L8: PayPal | M8: =VLOOKUP($E8,Customer_Dim!$A$2:$F$501,3,FALSE) -> Female | N8: =VLOOKUP($E8,Customer_Dim!$A$2:$F$501,5,FALSE) -> USA | O8: =VLOOKUP($E8,Customer_Dim!$A$2:$F$501,6,FALSE) -> Gold | P8: =VLOOKUP($A8,Store_Dim!$A$2:$F$21,3,FALSE) -> EastWashingtonfurt
A9: STORE0 | B9: SALE1808 | C9: PROD16 | D9: 45475 | E9: CUST1035 | F9: =VLOOKUP($C9,Product_Dim!$A$2:$D$101,3,FALSE) -> Erickson-Green | G9: =VLOOKUP($C9,Product_Dim!$A$2:$D$101,2,FALSE) -> Beauty | H9: 3 | I9: 168.89 | J9: 0.03 | K9: 491.4699 | L9: COD | M9: =VLOOKUP($E9,Customer_Dim!$A$2:$F$501,3,FALSE) -> Male | N9: =VLOOKUP($E9,Customer_Dim!$A$2:$F$501,5,FALSE) -> USA | O9: =VLOOKUP($E9,Customer_Dim!$A$2:$F$501,6,FALSE) -> Silver | P9: =VLOOKUP($A9,Store_Dim!$A$2:$F$21,3,FALSE) -> EastWashingtonfurt
A10: STORE0 | B10: SALE236 | C10: PROD17 | D10: 45809 | E10: CUST1169 | F10: =VLOOKUP($C10,Product_Dim!$A$2:$D$101,3,FALSE) -> Ford, Murphy and Wilson | G10: =VLOOKUP($C10,Product_Dim!$A$2:$D$101,2,FALSE) -> Sports | H10: 4 | I10: 469.68 | J10: 0.19 | K10: 1521.7632 | L10: Credit Card | M10: =VLOOKUP($E10,Customer_Dim!$A$2:$F$501,3,FALSE) -> Male | N10: =VLOOKUP($E10,Customer_Dim!$A$2:$F$501,5,FALSE) -> USA | O10: =VLOOKUP($E10,Customer_Dim!$A$2:$F$501,6,FALSE) -> Bronze | P10: =VLOOKUP($A10,Store_Dim!$A$2:$F$21,3,FALSE) -> EastWashingtonfurt
A11: STORE0 | B11: SALE1562 | C11: PROD17 | D11: 45582 | E11: CUST1389 | F11: =VLOOKUP($C11,Product_Dim!$A$2:$D$101,3,FALSE) -> Ford, Murphy and Wilson | G11: =VLOOKUP($C11,Product_Dim!$A$2:$D$101,2,FALSE) -> Sports | H11: 1 | I11: 465.63 | J11: 0.25 | K11: 349.2225 | L11: Credit Card | M11: =VLOOKUP($E11,Customer_Dim!$A$2:$F$501,3,FALSE) -> Male | N11: =VLOOKUP($E11,Customer_Dim!$A$2:$F$501,5,FALSE) -> USA | O11: =VLOOKUP($E11,Customer_Dim!$A$2:$F$501,6,FALSE) -> Platinum | P11: =VLOOKUP($A11,Store_Dim!$A$2:$F$21,3,FALSE) -> EastWashingtonfurt
A12: STORE0 | B12: SALE494 | C12: PROD18 | D12: 45501 | E12: CUST1240 | F12: =VLOOKUP($C12,Product_Dim!$A$2:$D$101,3,FALSE) -> Guerra-Hendrix | G12: =VLOOKUP($C12,Product_Dim!$A$2:$D$101,2,FALSE) -> Clothing | H12: 1 | I12: 917.17 | J12: 0.13 | K12: 797.9379 | L12: COD | M12: =VLOOKUP($E12,Customer_Dim!$A$2:$F$501,3,FALSE) -> Female | N12: =VLOOKUP($E12,Customer_Dim!$A$2:$F$501,5,FALSE) -> USA | O12: =VLOOKUP($E12,Customer_Dim!$A$2:$F$501,6,FALSE) -> Platinum | P12: =VLOOKUP($A12,Store_Dim!$A$2:$F$21,3,FALSE) -> EastWashingtonfurt
A13: STORE0 | B13: SALE843 | C13: PROD19 | D13: 45525 | E13: CUST1131 | F13: =VLOOKUP($C13,Product_Dim!$A$2:$D$101,3,FALSE) -> May-Reese | G13: =VLOOKUP($C13,Product_Dim!$A$2:$D$101,2,FALSE) -> Sports | H13: 1 | I13: 346.2 | J13: 0.29 | K13: 245.802 | L13: Credit Card | M13: =VLOOKUP($E13,Customer_Dim!$A$2:$F$501,3,FALSE) -> Female | N13: =VLOOKUP($E13,Customer_Dim!$A$2:$F$501,5,FALSE) -> USA | O13: =VLOOKUP($E13,Customer_Dim!$A$2:$F$501,6,FALSE) -> Bronze | P13: =VLOOKUP($A13,Store_Dim!$A$2:$F$21,3,FALSE) -> EastWashingtonfurt
... A159: STORE1 | B159: SALE379 | C159: PROD78 | D159: 45240 | E159: CUST1239 | F159: =VLOOKUP($C159,Product_Dim!$A$2:$D$101,3,FALSE) -> Hernandez Inc | G159: =VLOOKUP($C159,Product_Dim!$A$2:$D$101,2,FALSE) -> Home | H159: 3 | I159: 636.03 | J159: 0.06 | K159: 1793.6046 | L159: COD | M159: =VLOOKUP($E159,Customer_Dim!$A$2:$F$501,3,FALSE) -> Female | N159: =VLOOKUP($E159,Customer_Dim!$A$2:$F$501,5,FALSE) -> USA | O159: =VLOOKUP($E159,Customer_Dim!$A$2:$F$501,6,FALSE) -> Platinum | P159: =VLOOKUP($A159,Store_Dim!$A$2:$F$21,3,FALSE) -> NorthDanielmouth
A160: STORE1 | B160: SALE34 | C160: PROD79 | D160: 45215 | E160: CUST1344 | F160: =VLOOKUP($C160,Product_Dim!$A$2:$D$101,3,FALSE) -> Ramirez-Hanson | G160: =VLOOKUP($C160,Product_Dim!$A$2:$D$101,2,FALSE) -> Home | H160: =K160/(I160-J160) -> 2.4605072 | I160: 873.22 | J160: 0.18 | K160: 2148.1212 | L160: Credit Card | M160: =VLOOKUP($E160,Customer_Dim!$A$2:$F$501,3,FALSE) -> Male | N160: =VLOOKUP($E160,Customer_Dim!$A$2:$F$501,5,FALSE) -> USA | O160: =VLOOKUP($E160,Customer_Dim!$A$2:$F$501,6,FALSE) -> Gold | P160: =VLOOKUP($A160,Store_Dim!$A$2:$F$21,3,FALSE) -> NorthDanielmouth
A161: STORE1 | B161: SALE1101 | C161: PROD8 | D161: 45641 | E161: CUST1110 | F161: =VLOOKUP($C161,Product_Dim!$A$2:$D$101,3,FALSE) -> Perez-Johnston | G161: =VLOOKUP($C161,Product_Dim!$A$2:$D$101,2,FALSE) -> Electronics | H161: 3 | I161: 324.29 | J161: 0.16 | K161: 817.2108 | L161: COD | M161: =VLOOKUP($E161,Customer_Dim!$A$2:$F$501,3,FALSE) -> Female | N161: =VLOOKUP($E161,Customer_Dim!$A$2:$F$501,5,FALSE) -> USA | O161: =VLOOKUP($E161,Customer_Dim!$A$2:$F$501,6,FALSE) -> Gold | P161: =VLOOKUP($A161,Store_Dim!$A$2:$F$21,3,FALSE) -> NorthDanielmouth
A162: STORE1 | B162: SALE791 | C162: PROD8 | D162: 45320 | E162: CUST1134 | F162: =VLOOKUP($C162,Product_Dim!$A$2:$D$101,3,FALSE) -> Perez-Johnston | G162: =VLOOKUP($C162,Product_Dim!$A$2:$D$101,2,FALSE) -> Electronics | H162: 2 | I162: 443.09 | J162: 0.02 | K162: 868.4564 | L162: PayPal | M162: =VLOOKUP($E162,Customer_Dim!$A$2:$F$501,3,FALSE) -> Male | N162: =VLOOKUP($E162,Customer_Dim!$A$2:$F$501,5,FALSE) -> USA | O162: =VLOOKUP($E162,Customer_Dim!$A$2:$F$501,6,FALSE) -> Gold | P162: =VLOOKUP($A162,Store_Dim!$A$2:$F$21,3,FALSE) -> NorthDanielmouth
A163: STORE1 | B163: SALE696 | C163: PROD8 | D163: 45365 | E163: CUST1197 | F163: =VLOOKUP($C163,Product_Dim!$A$2:$D$101,3,FALSE) -> Perez-Johnston | G163: =VLOOKUP($C163,Product_Dim!$A$2:$D$101,2,FALSE) -> Electronics | H163: 4 | I163: 167.83 | J163: 0.15 | K163: 570.622 | L163: Credit Card | M163: =VLOOKUP($E163,Customer_Dim!$A$2:$F$501,3,FALSE) -> Female | N163: =VLOOKUP($E163,Customer_Dim!$A$2:$F$501,5,FALSE) -> USA | O163: =VLOOKUP($E163,Customer_Dim!$A$2:$F$501,6,FALSE) -> Platinum | P163: =VLOOKUP($A163,Store_Dim!$A$2:$F$21,3,FALSE) -> NorthDanielmouth
A164: STORE1 | B164: SALE1163 | C164: PROD81 | D164: 45691 | E164: CUST1242 | F164: =VLOOKUP($C164,Product_Dim!$A$2:$D$101,3,FALSE) -> Robinson-Brown | G164: =VLOOKUP($C164,Product_Dim!$A$2:$D$101,2,FALSE) -> Sports | H164: 1 | I164: 791.83 | J164: 0.28 | K164: 570.1176 | L164: PayPal | M164: =VLOOKUP($E164,Customer_Dim!$A$2:$F$501,3,FALSE) -> Female | N164: =VLOOKUP($E164,Customer_Dim!$A$2:$F$501,5,FALSE) -> USA | O164: =VLOOKUP($E164,Customer_Dim!$A$2:$F$501,6,FALSE) -> Silver | P164: =VLOOKUP($A164,Store_Dim!$A$2:$F$21,3,FALSE) -> NorthDanielmouth
A165: STORE1 | B165: SALE928 | C165: PROD81 | D165: 45637 | E165: CUST1381 | F165: =VLOOKUP($C165,Product_Dim!$A$2:$D$101,3,FALSE) -> Robinson-Brown | G165: =VLOOKUP($C165,Product_Dim!$A$2:$D$101,2,FALSE) -> Sports | H165: 3 | I165: 138.86 | J165: 0.11 | K165: 370.7562 | L165: PayPal | M165: =VLOOKUP($E165,Customer_Dim!$A$2:$F$501,3,FALSE) -> Male | N165: =VLOOKUP($E165,Customer_Dim!$A$2:$F$501,5,FALSE) -> USA | O165: =VLOOKUP($E165,Customer_Dim!$A$2:$F$501,6,FALSE) -> Silver | P165: =VLOOKUP($A165,Store_Dim!$A$2:$F$21,3,FALSE) -> NorthDanielmouth
A166: STORE1 | B166: SALE1849 | C166: PROD82 | D166: 45556 | E166: CUST1299 | F166: =VLOOKUP($C166,Product_Dim!$A$2:$D$101,3,FALSE) -> Reese-Watson | G166: =VLOOKUP($C166,Product_Dim!$A$2:$D$101,2,FALSE) -> Sports | H166: 4 | I166: 740.5 | J166: 0.17 | K166: 2458.46 | L166: PayPal | M166: =VLOOKUP($E166,Customer_Dim!$A$2:$F$501,3,FALSE) -> Female | N166: =VLOOKUP($E166,Customer_Dim!$A$2:$F$501,5,FALSE) -> USA | O166: =VLOOKUP($E166,Customer_Dim!$A$2:$F$501,6,FALSE) -> Platinum | P166: =VLOOKUP($A166,Store_Dim!$A$2:$F$21,3,FALSE) -> NorthDanielmouth
A167: STORE1 | B167: SALE1142 | C167: PROD83 | D167: 45608 | E167: CUST1296 | F167: =VLOOKUP($C167,Product_Dim!$A$2:$D$101,3,FALSE) -> Butler Group | G167: =VLOOKUP($C167,Product_Dim!$A$2:$D$101,2,FALSE) -> Beauty | H167: 3 | I167: 460.93 | J167: 0.19 | K167: 1120.0599 | L167: COD | M167: =VLOOKUP($E167,Customer_Dim!$A$2:$F$501,3,FALSE) -> Female | N167: =VLOOKUP($E167,Customer_Dim!$A$2:$F$501,5,FALSE) -> USA | O167: =VLOOKUP($E167,Customer_Dim!$A$2:$F$501,6,FALSE) -> Bronze | P167: =VLOOKUP($A167,Store_Dim!$A$2:$F$21,3,FALSE) -> NorthDanielmouth
A168: STORE1 | B168: SALE1088 | C168: PROD84 | D168: 45284 | E168: CUST1251 | F168: =VLOOKUP($C168,Product_Dim!$A$2:$D$101,3,FALSE) -> Collins-Stephenson | G168: =VLOOKUP($C168,Product_Dim!$A$2:$D$101,2,FALSE) -> Home | H168: 3 | I168: 204.77 | J168: 0.14 | K168: 528.3066 | L168: Credit Card | M168: =VLOOKUP($E168,Customer_Dim!$A$2:$F$501,3,FALSE) -> Male | N168: =VLOOKUP($E168,Customer_Dim!$A$2:$F$501,5,FALSE) -> USA | O168: =VLOOKUP($E168,Customer_Dim!$A$2:$F$501,6,FALSE) -> Silver | P168: =VLOOKUP($A168,Store_Dim!$A$2:$F$21,3,FALSE) -> NorthDanielmouth
A169: STORE1 | B169: SALE1099 | C169: PROD85 | D169: 45631 | E169: CUST1468 | F169: =VLOOKUP($C169,Product_Dim!$A$2:$D$101,3,FALSE) -> Richardson-Carrillo | G169: =VLOOKUP($C169,Product_Dim!$A$2:$D$101,2,FALSE) -> Clothing | H169: 1 | I169: 784.46 | J169: 0.14 | K169: 674.6356 | L169: COD | M169: =VLOOKUP($E169,Customer_Dim!$A$2:$F$501,3,FALSE) -> Male | N169: =VLOOKUP($E169,Customer_Dim!$A$2:$F$501,5,FALSE) -> USA | O169: =VLOOKUP($E169,Customer_Dim!$A$2:$F$501,6,FALSE) -> Bronze | P169: =VLOOKUP($A169,Store_Dim!$A$2:$F$21,3,FALSE) -> NorthDanielmouth
A170: STORE1 | B170: SALE1667 | C170: PROD86 | D170: 45860 | E170: CUST1312 | F170: =VLOOKUP($C170,Product_Dim!$A$2:$D$101,3,FALSE) -> Taylor, Dodson and Johnston | G170: =VLOOKUP($C170,Product_Dim!$A$2:$D$101,2,FALSE) -> Home | H170: 1 | I170: 119.04 | J170: 0.13 | K170: 103.5648 | L170: COD | M170: =VLOOKUP($E170,Customer_Dim!$A$2:$F$501,3,FALSE) -> Female | N170: =VLOOKUP($E170,Customer_Dim!$A$2:$F$501,5,FALSE) -> USA | O170: =VLOOKUP($E170,Customer_Dim!$A$2:$F$501,6,FALSE) -> Silver | P170: =VLOOKUP($A170,Store_Dim!$A$2:$F$21,3,FALSE) -> NorthDanielmouth
A171: STORE1 | B171: SALE462 | C171: PROD87 | D171: 45279 | E171: CUST1265 | F171: =VLOOKUP($C171,Product_Dim!$A$2:$D$101,3,FALSE) -> Aguilar, Horton and Lewis | G171: =VLOOKUP($C171,Product_Dim!$A$2:$D$101,2,FALSE) -> Home | H171: 2 | I171: 291.84 | J171: 0.25 | K171: 437.76 | L171: PayPal | M171: =VLOOKUP($E171,Customer_Dim!$A$2:$F$501,3,FALSE) -> Male | N171: =VLOOKUP($E171,Customer_Dim!$A$2:$F$501,5,FALSE) -> USA | O171: =VLOOKUP($E171,Customer_Dim!$A$2:$F$501,6,FALSE) -> Silver | P171: =VLOOKUP($A171,Store_Dim!$A$2:$F$21,3,FALSE) -> NorthDanielmouth
A172: STORE1 | B172: SALE1260 | C172: PROD87 | D172: 45323 | E172: CUST1363 | F172: =VLOOKUP($C172,Product_Dim!$A$2:$D$101,3,FALSE) -> Aguilar, Horton and Lewis | G172: =VLOOKUP($C172,Product_Dim!$A$2:$D$101,2,FALSE) -> Home | H172: 4 | I172: 800 | J172: 0.2 | K172: 2560 | L172: Credit Card | M172: =VLOOKUP($E172,Customer_Dim!$A$2:$F$501,3,FALSE) -> Male | N172: =VLOOKUP($E172,Customer_Dim!$A$2:$F$501,5,FALSE) -> USA | O172: =VLOOKUP($E172,Customer_Dim!$A$2:$F$501,6,FALSE) -> Bronze | P172: =VLOOKUP($A172,Store_Dim!$A$2:$F$21,3,FALSE) -> NorthDanielmouth
... A227: STORE10 | B227: SALE905 | C227: PROD52 | D227: 45799 | E227: CUST1392 | F227: =VLOOKUP($C227,Product_Dim!$A$2:$D$101,3,FALSE) -> Harris Inc | G227: =VLOOKUP($C227,Product_Dim!$A$2:$D$101,2,FALSE) -> Sports | H227: 2 | I227: 295.12 | J227: 0.09 | K227: 537.1184 | L227: COD | M227: =VLOOKUP($E227,Customer_Dim!$A$2:$F$501,3,FALSE) -> Male | N227: =VLOOKUP($E227,Customer_Dim!$A$2:$F$501,5,FALSE) -> USA | O227: =VLOOKUP($E227,Customer_Dim!$A$2:$F$501,6,FALSE) -> Gold | P227: =VLOOKUP($A227,Store_Dim!$A$2:$F$21,3,FALSE) -> EastEast Davidville
A228: STORE10 | B228: SALE64 | C228: PROD53 | D228: 45914 | E228: CUST1255 | F228: =VLOOKUP($C228,Product_Dim!$A$2:$D$101,3,FALSE) -> Hamilton, Woods and Walker | G228: =VLOOKUP($C228,Product_Dim!$A$2:$D$101,2,FALSE) -> Clothing | H228: 3 | I228: 480.06 | J228: 0.01 | K228: =H228*I228-J228 -> 1440.17 | L228: Credit Card | M228: =VLOOKUP($E228,Customer_Dim!$A$2:$F$501,3,FALSE) -> Male | N228: =VLOOKUP($E228,Customer_Dim!$A$2:$F$501,5,FALSE) -> USA | O228: =VLOOKUP($E228,Customer_Dim!$A$2:$F$501,6,FALSE) -> Gold | P228: =VLOOKUP($A228,Store_Dim!$A$2:$F$21,3,FALSE) -> EastEast Davidville
A229: STORE10 | B229: SALE1650 | C229: PROD53 | D229: 45929 | E229: CUST1355 | F229: =VLOOKUP($C229,Product_Dim!$A$2:$D$101,3,FALSE) -> Hamilton, Woods and Walker | G229: =VLOOKUP($C229,Product_Dim!$A$2:$D$101,2,FALSE) -> Clothing | H229: 1 | I229: 899.09 | J229: 0.2 | K229: 719.272 | L229: PayPal | M229: =VLOOKUP($E229,Customer_Dim!$A$2:$F$501,3,FALSE) -> Male | N229: =VLOOKUP($E229,Customer_Dim!$A$2:$F$501,5,FALSE) -> USA | O229: =VLOOKUP($E229,Customer_Dim!$A$2:$F$501,6,FALSE) -> Gold | P229: =VLOOKUP($A229,Store_Dim!$A$2:$F$21,3,FALSE) -> EastEast Davidville
A230: STORE10 | B230: SALE316 | C230: PROD54 | D230: 45435 | E230: CUST1262 | F230: =VLOOKUP($C230,Product_Dim!$A$2:$D$101,3,FALSE) -> Thompson-French | G230: =VLOOKUP($C230,Product_Dim!$A$2:$D$101,2,FALSE) -> Sports | H230: 3 | I230: 977.55 | J230: 0.02 | K230: 2873.997 | L230: PayPal | M230: =VLOOKUP($E230,Customer_Dim!$A$2:$F$501,3,FALSE) -> Female | N230: =VLOOKUP($E230,Customer_Dim!$A$2:$F$501,5,FALSE) -> USA | O230: =VLOOKUP($E230,Customer_Dim!$A$2:$F$501,6,FALSE) -> Silver | P230: =VLOOKUP($A230,Store_Dim!$A$2:$F$21,3,FALSE) -> EastEast Davidville
A231: STORE10 | B231: SALE813 | C231: PROD54 | D231: 45890 | E231: CUST1334 | F231: =VLOOKUP($C231,Product_Dim!$A$2:$D$101,3,FALSE) -> Thompson-French | G231: =VLOOKUP($C231,Product_Dim!$A$2:$D$101,2,FALSE) -> Sports | H231: 4 | I231: 250.64 | J231: 0.1 | K231: 902.304 | L231: PayPal | M231: =VLOOKUP($E231,Customer_Dim!$A$2:$F$501,3,FALSE) -> Female | N231: =VLOOKUP($E231,Customer_Dim!$A$2:$F$501,5,FALSE) -> USA | O231: =VLOOKUP($E231,Customer_Dim!$A$2:$F$501,6,FALSE) -> Silver | P231: =VLOOKUP($A231,Store_Dim!$A$2:$F$21,3,FALSE) -> EastEast Davidville
A232: STORE10 | B232: SALE1398 | C232: PROD57 | D232: 45601 | E232: CUST1133 | F232: =VLOOKUP($C232,Product_Dim!$A$2:$D$101,3,FALSE) -> Atkinson, Camacho and Oliver | G232: =VLOOKUP($C232,Product_Dim!$A$2:$D$101,2,FALSE) -> Sports | H232: 4 | I232: 559.59 | J232: 0.19 | K232: 1813.0716 | L232: COD | M232: =VLOOKUP($E232,Customer_Dim!$A$2:$F$501,3,FALSE) -> Female | N232: =VLOOKUP($E232,Customer_Dim!$A$2:$F$501,5,FALSE) -> USA | O232: =VLOOKUP($E232,Customer_Dim!$A$2:$F$501,6,FALSE) -> Bronze | P232: =VLOOKUP($A232,Store_Dim!$A$2:$F$21,3,FALSE) -> EastEast Davidville
A233: STORE10 | B233: SALE232 | C233: PROD58 | D233: 45409 | E233: CUST1148 | F233: =VLOOKUP($C233,Product_Dim!$A$2:$D$101,3,FALSE) -> Shepherd-Gould | G233: =VLOOKUP($C233,Product_Dim!$A$2:$D$101,2,FALSE) -> Clothing | H233: 4 | I233: 794.97 | J233: 0.24 | K233: 2416.7088 | L233: PayPal | M233: =VLOOKUP($E233,Customer_Dim!$A$2:$F$501,3,FALSE) -> Female | N233: =VLOOKUP($E233,Customer_Dim!$A$2:$F$501,5,FALSE) -> USA | O233: =VLOOKUP($E233,Customer_Dim!$A$2:$F$501,6,FALSE) -> Bronze | P233: =VLOOKUP($A233,Store_Dim!$A$2:$F$21,3,FALSE) -> EastEast Davidville
A234: STORE10 | B234: SALE1111 | C234: PROD58 | D234: 45316 | E234: CUST1274 | F234: =VLOOKUP($C234,Product_Dim!$A$2:$D$101,3,FALSE) -> Shepherd-Gould | G234: =VLOOKUP($C234,Product_Dim!$A$2:$D$101,2,FALSE) -> Clothing | H234: 1 | I234: 937.01 | J234: 0.07 | K234: 871.4193 | L234: Credit Card | M234: =VLOOKUP($E234,Customer_Dim!$A$2:$F$501,3,FALSE) -> Male | N234: =VLOOKUP($E234,Customer_Dim!$A$2:$F$501,5,FALSE) -> USA | O234: =VLOOKUP($E234,Customer_Dim!$A$2:$F$501,6,FALSE) -> Silver | P234: =VLOOKUP($A234,Store_Dim!$A$2:$F$21,3,FALSE) -> EastEast Davidville
A235: STORE10 | B235: SALE417 | C235: PROD58 | D235: 45331 | E235: CUST1383 | F235: =VLOOKUP($C235,Product_Dim!$A$2:$D$101,3,FALSE) -> Shepherd-Gould | G235: =VLOOKUP($C235,Product_Dim!$A$2:$D$101,2,FALSE) -> Clothing | H235: 2 | I235: 466.27 | J235: 0.11 | K235: 829.9606 | L235: PayPal | M235: =VLOOKUP($E235,Customer_Dim!$A$2:$F$501,3,FALSE) -> Female | N235: =VLOOKUP($E235,Customer_Dim!$A$2:$F$501,5,FALSE) -> USA | O235: =VLOOKUP($E235,Customer_Dim!$A$2:$F$501,6,FALSE) -> Silver | P235: =VLOOKUP($A235,Store_Dim!$A$2:$F$21,3,FALSE) -> EastEast Davidville
A236: STORE10 | B236: SALE602 | C236: PROD6 | D236: 45718 | E236: CUST1378 | F236: =VLOOKUP($C236,Product_Dim!$A$2:$D$101,3,FALSE) -> Davidson PLC | G236: =VLOOKUP($C236,Product_Dim!$A$2:$D$101,2,FALSE) -> Beauty | H236: 3 | I236: 483.06 | J236: 0.05 | K236: 1376.721 | L236: Credit Card | M236: =VLOOKUP($E236,Customer_Dim!$A$2:$F$501,3,FALSE) -> Female | N236: =VLOOKUP($E236,Customer_Dim!$A$2:$F$501,5,FALSE) -> USA | O236: =VLOOKUP($E236,Customer_Dim!$A$2:$F$501,6,FALSE) -> Bronze | P236: =VLOOKUP($A236,Store_Dim!$A$2:$F$21,3,FALSE) -> EastEast Davidville
A237: STORE10 | B237: SALE1568 | C237: PROD6 | D237: 45789 | E237: CUST1416 | F237: =VLOOKUP($C237,Product_Dim!$A$2:$D$101,3,FALSE) -> Davidson PLC | G237: =VLOOKUP($C237,Product_Dim!$A$2:$D$101,2,FALSE) -> Beauty | H237: 4 | I237: 458.58 | J237: 0.29 | K237: 1302.3672 | L237: COD | M237: =VLOOKUP($E237,Customer_Dim!$A$2:$F$501,3,FALSE) -> Male | N237: =VLOOKUP($E237,Customer_Dim!$A$2:$F$501,5,FALSE) -> USA | O237: =VLOOKUP($E237,Customer_Dim!$A$2:$F$501,6,FALSE) -> Platinum | P237: =VLOOKUP($A237,Store_Dim!$A$2:$F$21,3,FALSE) -> EastEast Davidville
A238: STORE10 | B238: SALE1261 | C238: PROD60 | D238: 45889 | E238: CUST1155 | F238: =VLOOKUP($C238,Product_Dim!$A$2:$D$101,3,FALSE) -> Gibson, Green and Lopez | G238: =VLOOKUP($C238,Product_Dim!$A$2:$D$101,2,FALSE) -> Beauty | H238: 3 | I238: 118.25 | J238: 0.26 | K238: 262.515 | L238: PayPal | M238: =VLOOKUP($E238,Customer_Dim!$A$2:$F$501,3,FALSE) -> Female | N238: =VLOOKUP($E238,Customer_Dim!$A$2:$F$501,5,FALSE) -> USA | O238: =VLOOKUP($E238,Customer_Dim!$A$2:$F$501,6,FALSE) -> Gold | P238: =VLOOKUP($A238,Store_Dim!$A$2:$F$21,3,FALSE) -> EastEast Davidville
A239: STORE10 | B239: SALE851 | C239: PROD60 | D239: 45484 | E239: CUST1320 | F239: =VLOOKUP($C239,Product_Dim!$A$2:$D$101,3,FALSE) -> Gibson, Green and Lopez | G239: =VLOOKUP($C239,Product_Dim!$A$2:$D$101,2,FALSE) -> Beauty | H239: 4 | I239: 597.8 | J239: 0.2 | K239: 1912.96 | L239: Credit Card | M239: =VLOOKUP($E239,Customer_Dim!$A$2:$F$501,3,FALSE) -> Female | N239: =VLOOKUP($E239,Customer_Dim!$A$2:$F$501,5,FALSE) -> USA | O239: =VLOOKUP($E239,Customer_Dim!$A$2:$F$501,6,FALSE) -> Bronze | P239: =VLOOKUP($A239,Store_Dim!$A$2:$F$21,3,FALSE) -> EastEast Davidville
...

Sheet SHEET 1
G4: DESCRIPTIVE STATISTICS OF UNIT PRICE DISCOUNT TOTAL AMOUNT
H9: Unit_Price | J9: Discount | L9: Total_Amount
H11: Mean | I11: 513.5701 | J11: Mean | K11: 0.14864 | L11: Mean | M11: 1087.2681
H12: Standard Error | I12: 6.3136507 | J12: Standard Error | K12: 0.0020223551 | L12: Standard Error | M12: 18.326242
H13: Median | I13: 522.43 | J13: Median | K13: 0.14 | L13: Median | M13: 868.7182
H14: Mode | I14: 503.95 | J14: Mode | K14: 0.1 | L14: Mode | M14: #N/A
H15: Standard Deviation | I15: 282.35504 | J15: Standard Deviation | K15: 0.09044247 | L15: Standard Deviation | M15: 819.57444
H16: Sample Variance | I16: 79724.37 | J16: Sample Variance | K16: 0.0081798403 | L16: Sample Variance | M16: 671702.27
H17: Kurtosis | I17: -1.1932255 | J17: Kurtosis | K17: 2.2279712 | L17: Kurtosis | M17: 0.045970018
H18: Skewness | I18: -0.034754918 | J18: Skewness | K18: 0.50291428 | L18: Skewness | M18: 0.87909943
H19: Range | I19: 979.8 | J19: Range | K19: 0.87 | L19: Range | M19: 3889.7838
H20: Minimum | I20: 20.09 | J20: Minimum | K20: 0 | L20: Minimum | M20: 18.459
H21: Maximum | I21: 999.89 | J21: Maximum | K21: 0.87 | L21: Maximum | M21: 3908.2428
H22: Sum | I22: 1027140.2 | J22: Sum | K22: 297.28 | L22: Sum | M22: 2174536.3
H23: Count | I23: 2000 | J23: Count | K23: 2000 | L23: Count | M23: 2000
D26: Total revenue by male customers | H26: =SUMIF(Sales_Fact!M2:M1996,"Male",Sales_Fact!K2:K1996) -> 943092.07
D27: TOTal revenue GENERATED | H27: =SUM(Sales_Fact!K2:K1996) -> 2168228.4

Sheet Sheet1
A1: Row Labels | B1: Sum of 264.94
A2: STORE0 | B2: 84873.616
A3: STORE1 | B3: 101060.61
A4: STORE10 | B4: 109806.11
A5: STORE11 | B5: 93048.14
A6: STORE12 | B6: 116829.22
A7: STORE13 | B7: 114401.47
A8: STORE14 | B8: 106248.28
A9: STORE15 | B9: 99679.086
A10: STORE16 | B10: 111704.94
A11: STORE17 | B11: 122215.18
A12: STORE18 | B12: 104313.05
A13: STORE19 | B13: 94237.101
... A22: Grand Total | B22: 2167963.5
A24: Row Labels | B24: Sum of 1
A25: Beauty | B25: 736
A26: Clothing | B26: 841.88013
A27: Electronics | B27: 1164
A28: Home | B28: 966.81277
A29: Sports | B29: 1241
A30: Grand Total | B30: 4949.6929
A33: Row Labels | B33: Sum of Total_Amount
A34: COD | B34: 701094.19
A35: Credit Card | B35: 713068.81
A36: PayPal | B36: 754065.43
A37: Grand Total | B37: 2168228.4
A41: Row Labels | B41: Sum of Discount
A42: Bronze | B42: 73.02
A43: Gold | B43: 68.61
A44: Platinum | B44: 90.59
A45: Silver | B45: 62.22
A46: UNKNOWN | B46: 2.22
A47: Grand Total | B47: 296.66

Sheet Sheet2
G1: ECOMMERCE DATASET ANALYSIS AND INSIGHTS

Sheet Sheet3
A1: Age | B1: Loyalty_Level | C1: Forecast(Loyalty_Level) | D1: Lower Confidence Bound(Loyalty_Level) | E1: Upper Confidence Bound(Loyalty_Level)
A2: 18 | B2: 13
A3: 19 | B3: 7
A4: 20 | B4: 6
A5: 21 | B5: 14
A6: 22 | B6: 9
A7: 23 | B7: 12
A8: 24 | B8: 8
A9: 25 | B9: 8
A10: 26 | B10: 11
A11: 27 | B11: 14
A12: 28 | B12: 10
A13: 29 | B13: 17
... A47: 63 | B47: 7
A48: 64 | B48: 16 | C48: 16 | D48: 16 | E48: 16
A49: 65 | C49: =_xlfn.FORECAST.ETS(A49,$B$2:$B$48,$A$2:$A$48,1,1) -> 8.3340769 | D49: =C49-_xlfn.FORECAST.ETS.CONFINT(A49,$B$2:$B$48,$A$2:$A$48,0.95,1,1) -> 1.0155919 | E49: =C49+_xlfn.FORECAST.ETS.CONFINT(A49,$B$2:$B$48,$A$2:$A$48,0.95,1,1) -> 15.652562
A50: 66 | C50: =_xlfn.FORECAST.ETS(A50,$B$2:$B$48,$A$2:$A$48,1,1) -> 14.184808 | D50: =C50-_xlfn.FORECAST.ETS.CONFINT(A50,$B$2:$B$48,$A$2:$A$48,0.95,1,1) -> 6.8662899 | E50: =C50+_xlfn.FORECAST.ETS.CONFINT(A50,$B$2:$B$48,$A$2:$A$48,0.95,1,1) -> 21.503326
A51: 67 | C51: =_xlfn.FORECAST.ETS(A51,$B$2:$B$48,$A$2:$A$48,1,1) -> 8.3522106 | D51: =C51-_xlfn.FORECAST.ETS.CONFINT(A51,$B$2:$B$48,$A$2:$A$48,0.95,1,1) -> 0.80130364 | E51: =C51+_xlfn.FORECAST.ETS.CONFINT(A51,$B$2:$B$48,$A$2:$A$48,0.95,1,1) -> 15.903118
A52: 68 | C52: =_xlfn.FORECAST.ETS(A52,$B$2:$B$48,$A$2:$A$48,1,1) -> 14.202942 | D52: =C52-_xlfn.FORECAST.ETS.CONFINT(A52,$B$2:$B$48,$A$2:$A$48,0.95,1,1) -> 6.6519459 | E52: =C52+_xlfn.FORECAST.ETS.CONFINT(A52,$B$2:$B$48,$A$2:$A$48,0.95,1,1) -> 21.753937
A53: 69 | C53: =_xlfn.FORECAST.ETS(A53,$B$2:$B$48,$A$2:$A$48,1,1) -> 8.3703443 | D53: =C53-_xlfn.FORECAST.ETS.CONFINT(A53,$B$2:$B$48,$A$2:$A$48,0.95,1,1) -> 0.59039201 | E53: =C53+_xlfn.FORECAST.ETS.CONFINT(A53,$B$2:$B$48,$A$2:$A$48,0.95,1,1) -> 16.150297
A54: 70 | C54: =_xlfn.FORECAST.ETS(A54,$B$2:$B$48,$A$2:$A$48,1,1) -> 14.221075 | D54: =C54-_xlfn.FORECAST.ETS.CONFINT(A54,$B$2:$B$48,$A$2:$A$48,0.95,1,1) -> 6.4409543 | E54: =C54+_xlfn.FORECAST.ETS.CONFINT(A54,$B$2:$B$48,$A$2:$A$48,0.95,1,1) -> 22.001196
A55: 71 | C55: =_xlfn.FORECAST.ETS(A55,$B$2:$B$48,$A$2:$A$48,1,1) -> 8.388478 | D55: =C55-_xlfn.FORECAST.ETS.CONFINT(A55,$B$2:$B$48,$A$2:$A$48,0.95,1,1) -> 0.38251368 | E55: =C55+_xlfn.FORECAST.ETS.CONFINT(A55,$B$2:$B$48,$A$2:$A$48,0.95,1,1) -> 16.394442
A56: 72 | C56: =_xlfn.FORECAST.ETS(A56,$B$2:$B$48,$A$2:$A$48,1,1) -> 14.239209 | D56: =C56-_xlfn.FORECAST.ETS.CONFINT(A56,$B$2:$B$48,$A$2:$A$48,0.95,1,1) -> 6.2329737 | E56: =C56+_xlfn.FORECAST.ETS.CONFINT(A56,$B$2:$B$48,$A$2:$A$48,0.95,1,1) -> 22.245444
A57: 73 | C57: =_xlfn.FORECAST.ETS(A57,$B$2:$B$48,$A$2:$A$48,1,1) -> 8.4066117 | D57: =C57-_xlfn.FORECAST.ETS.CONFINT(A57,$B$2:$B$48,$A$2:$A$48,0.95,1,1) -> 0.17736665 | E57: =C57+_xlfn.FORECAST.ETS.CONFINT(A57,$B$2:$B$48,$A$2:$A$48,0.95,1,1) -> 16.635857
A58: 74 | C58: =_xlfn.FORECAST.ETS(A58,$B$2:$B$48,$A$2:$A$48,1,1) -> 14.257343 | D58: =C58-_xlfn.FORECAST.ETS.CONFINT(A58,$B$2:$B$48,$A$2:$A$48,0.95,1,1) -> 6.0277038 | E58: =C58+_xlfn.FORECAST.ETS.CONFINT(A58,$B$2:$B$48,$A$2:$A$48,0.95,1,1) -> 22.486981
A59: 75 | C59: =_xlfn.FORECAST.ETS(A59,$B$2:$B$48,$A$2:$A$48,1,1) -> 8.4247454 | D59: =C59-_xlfn.FORECAST.ETS.CONFINT(A59,$B$2:$B$48,$A$2:$A$48,0.95,1,1) -> -0.025316297 | E59: =C59+_xlfn.FORECAST.ETS.CONFINT(A59,$B$2:$B$48,$A$2:$A$48,0.95,1,1) -> 16.874807
A60: 76 | C60: =_xlfn.FORECAST.ETS(A60,$B$2:$B$48,$A$2:$A$48,1,1) -> 14.275476 | D60: =C60-_xlfn.FORECAST.ETS.CONFINT(A60,$B$2:$B$48,$A$2:$A$48,0.95,1,1) -> 5.8248791 | E60: =C60+_xlfn.FORECAST.ETS.CONFINT(A60,$B$2:$B$48,$A$2:$A$48,0.95,1,1) -> 22.726074
